File: Phys-PK1_Si.csv
[Measurement conditions]
Sample identification,
Comment - 1,"Configuration=Reflection/Transmission, Owner=paul, Creation date=20/02/2013 12:06:42"
Comment - 2,"Goniometer=Omega/2Theta; Minimum step size 2Theta:0.0001; Minimum step size Omega:0.0001"
Comment - 3,"Sample stage=Reflection-transmission spinner; Minimum step size Phi:0.1"
Comment - 4,"Diffractometer system=EMPYREAN"
Comment - 5,"Measurement program=C:\PANalytical\Data Collector\Programs\John 25-85 1hr.xrdmp, Identifier={3B1BC07C-5EEF-4B0E-BF62-D7CE978FAC28}"
Comment - 6,"Batch program=C:\PANalytical\Data Collector\Programs\131219.xrdmp, Identifier={31C38298-C37B-48FA-AEC9-5BAA06322F9D}"
Comment - 7,""
Anode material,Cu
K-Alpha1 wavelength,1.5405980
K-Alpha2 wavelength,1.5444260
Ratio K-Alpha2/K-Alpha1,0.000
Divergence slit,Fixed,1.000
Receiving slit,0.10
Monochromator used,NO
Generator voltage, 45
Tube current, 40
File date and time,13/Dec/2019 19:37
Unit cell,
h k l, 0 0 0
Temperature [K],298
Scan axis,Gonio
Scan range,25.0065,84.9995
Scan step size,0.0170000
No. of points, 3529
Scan type,CONTINUOUS
Time per step,121.920
[Scan points]
Angle,Intensity
25.0150,306.0
25.0660,261.0
25.1170,258.0
25.1680,284.0
25.2190,276.0
25.2700,277.0
25.3210,279.0
25.3720,282.0
25.4230,268.0
25.4740,291.0
25.5250,283.0
25.5760,281.0
25.6270,271.0
25.6780,262.0
25.7290,266.0
25.7800,256.0
25.8310,274.0
25.8820,295.0
25.9330,239.0
25.9840,267.0
26.0350,253.0
26.0860,290.0
26.1370,267.0
26.1880,237.0
26.2390,254.0
26.2900,253.0
26.3410,262.0
26.3920,264.0
26.4430,266.0
26.4940,266.0
26.5450,259.0
26.5960,239.0
26.6470,254.0
26.6980,260.0
26.7490,260.0
26.8000,252.0
26.8510,274.0
26.9020,289.0
26.9530,226.0
27.0040,248.0
27.0550,241.0
27.1060,236.0
27.1570,253.0
27.2080,250.0
27.2590,260.0
27.3100,248.0
27.3610,241.0
27.4120,241.0
27.4630,253.0
27.5140,237.0
27.5650,237.0
27.6160,236.0
27.6670,222.0
27.7180,228.0
27.7690,253.0
27.8200,253.0
27.8710,273.0
27.9220,299.0
27.9730,291.0
28.0240,318.0
28.0750,267.0
28.1260,333.0
28.1770,376.0
28.2280,372.0
28.2790,283.0
28.3300,290.0
28.3810,304.0
28.4320,279.0
28.4830,298.0
28.5340,292.0
28.5850,325.0
28.6360,324.0
28.6870,418.0
28.7380,472.0
28.7890,661.0
28.8400,756.0
28.8910,610.0
28.9420,430.0
28.9930,391.0
29.0440,371.0
29.0950,318.0
29.1460,265.0
29.1970,272.0
29.2480,261.0
29.2990,274.0
29.3500,252.0
29.4010,240.0
29.4520,248.0
29.5030,256.0
29.5540,243.0
29.6050,222.0
29.6560,246.0
29.7070,231.0
29.7580,233.0
29.8090,198.0
29.8600,196.0
29.9110,234.0
29.9620,239.0
30.0130,207.0
30.0640,214.0
30.1150,194.0
30.1660,198.0
30.2170,200.0
30.2680,180.0
30.3190,199.0
30.3700,205.0
30.4210,199.0
30.4720,213.0
30.5230,188.0
30.5740,218.0
30.6250,201.0
30.6760,205.0
30.7270,184.0
30.7780,198.0
30.8290,204.0
30.8800,193.0
30.9310,199.0
30.9820,188.0
31.0330,209.0
31.0840,179.0
31.1350,203.0
31.1860,197.0
31.2370,191.0
31.2880,185.0
31.3390,185.0
31.3900,194.0
31.4410,180.0
31.4920,165.0
31.5430,172.0
31.5940,185.0
31.6450,177.0
31.6960,176.0
31.7470,203.0
31.7980,169.0
31.8490,204.0
31.9000,186.0
31.9510,174.0
32.0020,174.0
32.0530,171.0
32.1040,190.0
32.1550,179.0
32.2060,212.0
32.2570,184.0
32.3080,174.0
32.3590,203.0
32.4100,218.0
32.4610,192.0
32.5120,168.0
32.5630,183.0
32.6140,178.0
32.6650,178.0
32.7160,171.0
32.7670,174.0
32.8180,179.0
32.8690,171.0
32.9200,196.0
32.9710,166.0
33.0220,169.0
33.0730,176.0
33.1240,173.0
33.1750,162.0
33.2260,157.0
33.2770,163.0
33.3280,169.0
33.3790,161.0
33.4300,163.0
33.4810,177.0
33.5320,172.0
33.5830,168.0
33.6340,158.0
33.6850,177.0
33.7360,190.0
33.7870,176.0
33.8380,178.0
33.8890,170.0
33.9400,175.0
33.9910,191.0
34.0420,194.0
34.0930,197.0
34.1440,198.0
34.1950,199.0
34.2460,185.0
34.2970,176.0
34.3480,189.0
34.3990,173.0
34.4500,180.0
34.5010,193.0
34.5520,210.0
34.6030,222.0
34.6540,219.0
34.7050,247.0
34.7560,315.0
34.8070,409.0
34.8580,549.0
34.9090,626.0
34.9600,416.0
35.0110,338.0
35.0620,247.0
35.1130,225.0
35.1640,213.0
35.2150,217.0
35.2660,196.0
35.3170,177.0
35.3680,157.0
35.4190,164.0
35.4700,170.0
35.5210,187.0
35.5720,172.0
35.6230,163.0
35.6740,159.0
35.7250,164.0
35.7760,155.0
35.8270,168.0
35.8780,174.0
35.9290,172.0
35.9800,158.0
36.0310,174.0
36.0820,160.0
36.1330,146.0
36.1840,168.0
36.2350,169.0
36.2860,183.0
36.3370,183.0
36.3880,148.0
36.4390,166.0
36.4900,154.0
36.5410,154.0
36.5920,157.0
36.6430,135.0
36.6940,168.0
36.7450,185.0
36.7960,163.0
36.8470,190.0
36.8980,318.0
36.9490,319.0
37.0000,220.0
37.0510,165.0
37.1020,161.0
37.1530,166.0
37.2040,160.0
37.2550,172.0
37.3060,180.0
37.3570,222.0
37.4080,204.0
37.4590,190.0
37.5100,196.0
37.5610,196.0
37.6120,165.0
37.6630,166.0
37.7140,186.0
37.7650,194.0
37.8160,185.0
37.8670,177.0
37.9180,186.0
37.9690,178.0
38.0200,186.0
38.0710,180.0
38.1220,190.0
38.1730,162.0
38.2240,179.0
38.2750,185.0
38.3260,196.0
38.3770,237.0
38.4280,245.0
38.4790,198.0
38.5300,153.0
38.5810,145.0
38.6320,147.0
38.6830,129.0
38.7340,135.0
38.7850,154.0
38.8360,133.0
38.8870,138.0
38.9380,140.0
38.9890,136.0
39.0400,143.0
39.0910,138.0
39.1420,142.0
39.1930,138.0
39.2440,137.0
39.2950,159.0
39.3460,162.0
39.3970,154.0
39.4480,169.0
39.4990,161.0
39.5500,145.0
39.6010,148.0
39.6520,149.0
39.7030,140.0
39.7540,161.0
39.8050,144.0
39.8560,134.0
39.9070,147.0
39.9580,169.0
40.0090,159.0
40.0600,150.0
40.1110,156.0
40.1620,162.0
40.2130,157.0
40.2640,169.0
40.3150,181.0
40.3660,197.0
40.4170,201.0
40.4680,217.0
40.5190,228.0
40.5700,250.0
40.6210,304.0
40.6720,400.0
40.7230,539.0
40.7740,485.0
40.8250,340.0
40.8760,304.0
40.9270,302.0
40.9780,276.0
41.0290,312.0
41.0800,333.0
41.1310,338.0
41.1820,403.0
41.2330,500.0
41.2840,669.0
41.3350,1039.0
41.3860,1173.0
41.4370,823.0
41.4880,554.0
41.5390,400.0
41.5900,323.0
41.6410,252.0
41.6920,257.0
41.7430,249.0
41.7940,240.0
41.8450,188.0
41.8960,198.0
41.9470,178.0
41.9980,156.0
42.0490,170.0
42.1000,155.0
42.1510,154.0
42.2020,144.0
42.2530,140.0
42.3040,147.0
42.3550,135.0
42.4060,136.0
42.4570,132.0
42.5080,125.0
42.5590,121.0
42.6100,128.0
42.6610,118.0
42.7120,123.0
42.7630,133.0
42.8140,132.0
42.8650,119.0
42.9160,112.0
42.9670,120.0
43.0180,121.0
43.0690,119.0
43.1200,117.0
43.1710,117.0
43.2220,116.0
43.2730,131.0
43.3240,126.0
43.3750,119.0
43.4260,110.0
43.4770,113.0
43.5280,110.0
43.5790,114.0
43.6300,121.0
43.6810,122.0
43.7320,113.0
43.7830,109.0
43.8340,128.0
43.8850,118.0
43.9360,114.0
43.9870,111.0
44.0380,112.0
44.0890,108.0
44.1400,117.0
44.1910,111.0
44.2420,109.0
44.2930,105.0
44.3440,118.0
44.3950,112.0
44.4460,118.0
44.4970,121.0
44.5480,125.0
44.5990,128.0
44.6500,125.0
44.7010,111.0
44.7520,117.0
44.8030,116.0
44.8540,115.0
44.9050,107.0
44.9560,114.0
45.0070,105.0
45.0580,101.0
45.1090,101.0
45.1600,117.0
45.2110,106.0
45.2620,100.0
45.3130,106.0
45.3640,114.0
45.4150,103.0
45.4660,97.0
45.5170,103.0
45.5680,100.0
45.6190,103.0
45.6700,94.0
45.7210,92.0
45.7720,97.0
45.8230,113.0
45.8740,90.0
45.9250,111.0
45.9760,94.0
46.0270,101.0
46.0780,108.0
46.1290,117.0
46.1800,128.0
46.2310,124.0
46.2820,115.0
46.3330,110.0
46.3840,114.0
46.4350,110.0
46.4860,109.0
46.5370,113.0
46.5880,96.0
46.6390,100.0
46.6900,122.0
46.7410,105.0
46.7920,105.0
46.8430,131.0
46.8940,120.0
46.9450,126.0
46.9960,128.0
47.0470,205.0
47.0980,165.0
47.1490,129.0
47.2000,102.0
47.2510,112.0
47.3020,99.0
47.3530,113.0
47.4040,96.0
47.4550,107.0
47.5060,105.0
47.5570,96.0
47.6080,102.0
47.6590,109.0
47.7100,102.0
47.7610,116.0
47.8120,97.0
47.8630,105.0
47.9140,112.0
47.9650,118.0
48.0160,109.0
48.0670,101.0
48.1180,112.0
48.1690,104.0
48.2200,94.0
48.2710,106.0
48.3220,97.0
48.3730,104.0
48.4240,100.0
48.4750,95.0
48.5260,97.0
48.5770,96.0
48.6280,107.0
48.6790,103.0
48.7300,93.0
48.7810,102.0
48.8320,104.0
48.8830,101.0
48.9340,95.0
48.9850,93.0
49.0360,95.0
49.0870,105.0
49.1380,96.0
49.1890,95.0
49.2400,111.0
49.2910,94.0
49.3420,96.0
49.3930,95.0
49.4440,94.0
49.4950,111.0
49.5460,98.0
49.5970,112.0
49.6480,105.0
49.6990,116.0
49.7500,105.0
49.8010,101.0
49.8520,103.0
49.9030,94.0
49.9540,91.0
50.0050,102.0
50.0560,101.0
50.1070,100.0
50.1580,100.0
50.2090,103.0
50.2600,96.0
50.3110,95.0
50.3620,96.0
50.4130,120.0
50.4640,112.0
50.5150,105.0
50.5660,131.0
50.6170,154.0
50.6680,134.0
50.7190,152.0
50.7700,207.0
50.8210,235.0
50.8720,196.0
50.9230,157.0
50.9740,120.0
51.0250,116.0
51.0760,117.0
51.1270,108.0
51.1780,110.0
51.2290,105.0
51.2800,107.0
51.3310,120.0
51.3820,112.0
51.4330,108.0
51.4840,100.0
51.5350,93.0
51.5860,113.0
51.6370,112.0
51.6880,101.0
51.7390,99.0
51.7900,98.0
51.8410,109.0
51.8920,101.0
51.9430,104.0
51.9940,107.0
52.0450,110.0
52.0960,102.0
52.1470,92.0
52.1980,98.0
52.2490,93.0
52.3000,100.0
52.3510,101.0
52.4020,102.0
52.4530,101.0
52.5040,93.0
52.5550,116.0
52.6060,102.0
52.6570,105.0
52.7080,89.0
52.7590,102.0
52.8100,105.0
52.8610,104.0
52.9120,105.0
52.9630,101.0
53.0140,104.0
53.0650,102.0
53.1160,116.0
53.1670,107.0
53.2180,105.0
53.2690,117.0
53.3200,86.0
53.3710,100.0
53.4220,90.0
53.4730,103.0
53.5240,84.0
53.5750,95.0
53.6260,111.0
53.6770,107.0
53.7280,111.0
53.7790,109.0
53.8300,107.0
53.8810,109.0
53.9320,101.0
53.9830,115.0
54.0340,111.0
54.0850,108.0
54.1360,127.0
54.1870,115.0
54.2380,110.0
54.2890,113.0
54.3400,110.0
54.3910,116.0
54.4420,111.0
54.4930,112.0
54.5440,108.0
54.5950,114.0
54.6460,110.0
54.6970,110.0
54.7480,115.0
54.7990,118.0
54.8500,124.0
54.9010,120.0
54.9520,116.0
55.0030,121.0
55.0540,112.0
55.1050,117.0
55.1560,119.0
55.2070,116.0
55.2580,124.0
55.3090,125.0
55.3600,125.0
55.4110,119.0
55.4620,126.0
55.5130,132.0
55.5640,140.0
55.6150,128.0
55.6660,164.0
55.7170,159.0
55.7680,182.0
55.8190,195.0
55.8700,181.0
55.9210,172.0
55.9720,150.0
56.0230,139.0
56.0740,136.0
56.1250,132.0
56.1760,133.0
56.2270,125.0
56.2780,117.0
56.3290,124.0
56.3800,124.0
56.4310,113.0
56.4820,129.0
56.5330,132.0
56.5840,121.0
56.6350,122.0
56.6860,119.0
56.7370,122.0
56.7880,112.0
56.8390,114.0
56.8900,107.0
56.9410,120.0
56.9920,118.0
57.0430,113.0
57.0940,118.0
57.1450,113.0
57.1960,123.0
57.2470,121.0
57.2980,108.0
57.3490,107.0
57.4000,132.0
57.4510,110.0
57.5020,110.0
57.5530,110.0
57.6040,94.0
57.6550,115.0
57.7060,121.0
57.7570,108.0
57.8080,112.0
57.8590,112.0
57.9100,123.0
57.9610,123.0
58.0120,117.0
58.0630,141.0
58.1140,156.0
58.1650,167.0
58.2160,156.0
58.2670,127.0
58.3180,117.0
58.3690,113.0
58.4200,125.0
58.4710,106.0
58.5220,106.0
58.5730,124.0
58.6240,123.0
58.6750,109.0
58.7260,104.0
58.7770,106.0
58.8280,114.0
58.8790,104.0
58.9300,114.0
58.9810,109.0
59.0320,111.0
59.0830,120.0
59.1340,105.0
59.1850,109.0
59.2360,110.0
59.2870,98.0
59.3380,116.0
59.3890,122.0
59.4400,109.0
59.4910,111.0
59.5420,107.0
59.5930,104.0
59.6440,110.0
59.6950,118.0
59.7460,111.0
59.7970,107.0
59.8480,109.0
59.8990,110.0
59.9500,116.0
60.0010,120.0
60.0520,117.0
60.1030,121.0
60.1540,121.0
60.2050,111.0
60.2560,112.0
60.3070,111.0
60.3580,118.0
60.4090,110.0
60.4600,110.0
60.5110,120.0
60.5620,106.0
60.6130,119.0
60.6640,108.0
60.7150,113.0
60.7660,102.0
60.8170,110.0
60.8680,95.0
60.9190,108.0
60.9700,106.0
61.0210,98.0
61.0720,102.0
61.1230,105.0
61.1740,110.0
61.2250,109.0
61.2760,102.0
61.3270,105.0
61.3780,110.0
61.4290,104.0
61.4800,104.0
61.5310,111.0
61.5820,102.0
61.6330,100.0
61.6840,102.0
61.7350,108.0
61.7860,102.0
61.8370,112.0
61.8880,108.0
61.9390,96.0
61.9900,109.0
62.0410,102.0
62.0920,101.0
62.1430,91.0
62.1940,110.0
62.2450,103.0
62.2960,107.0
62.3470,114.0
62.3980,111.0
62.4490,101.0
62.5000,102.0
62.5510,99.0
62.6020,110.0
62.6530,113.0
62.7040,105.0
62.7550,108.0
62.8060,110.0
62.8570,97.0
62.9080,109.0
62.9590,104.0
63.0100,99.0
63.0610,95.0
63.1120,104.0
63.1630,92.0
63.2140,104.0
63.2650,89.0
63.3160,96.0
63.3670,114.0
63.4180,105.0
63.4690,88.0
63.5200,108.0
63.5710,113.0
63.6220,114.0
63.6730,117.0
63.7240,95.0
63.7750,100.0
63.8260,105.0
63.8770,110.0
63.9280,109.0
63.9790,104.0
64.0300,107.0
64.0810,113.0
64.1320,122.0
64.1830,124.0
64.2340,119.0
64.2850,116.0
64.3360,109.0
64.3870,119.0
64.4380,105.0
64.4890,115.0
64.5400,100.0
64.5910,93.0
64.6420,109.0
64.6930,104.0
64.7440,97.0
64.7950,95.0
64.8460,101.0
64.8970,100.0
64.9480,115.0
64.9990,92.0
65.0500,98.0
65.1010,94.0
65.1520,96.0
65.2030,98.0
65.2540,103.0
65.3050,93.0
65.3560,101.0
65.4070,115.0
65.4580,111.0
65.5090,96.0
65.5600,98.0
65.6110,105.0
65.6620,97.0
65.7130,96.0
65.7640,104.0
65.8150,108.0
65.8660,95.0
65.9170,100.0
65.9680,101.0
66.0190,112.0
66.0700,111.0
66.1210,103.0
66.1720,102.0
66.2230,108.0
66.2740,116.0
66.3250,128.0
66.3760,124.0
66.4270,111.0
66.4780,123.0
66.5290,111.0
66.5800,108.0
66.6310,110.0
66.6820,115.0
66.7330,115.0
66.7840,113.0
66.8350,110.0
66.8860,111.0
66.9370,116.0
66.9880,118.0
67.0390,111.0
67.0900,119.0
67.1410,122.0
67.1920,119.0
67.2430,119.0
67.2940,127.0
67.3450,119.0
67.3960,154.0
67.4470,157.0
67.4980,182.0
67.5490,213.0
67.6000,286.0
67.6510,341.0
67.7020,367.0
67.7530,280.0
67.8040,228.0
67.8550,183.0
67.9060,161.0
67.9570,147.0
68.0080,134.0
68.0590,131.0
68.1100,125.0
68.1610,110.0
68.2120,118.0
68.2630,117.0
68.3140,129.0
68.3650,129.0
68.4160,124.0
68.4670,118.0
68.5180,128.0
68.5690,115.0
68.6200,121.0
68.6710,106.0
68.7220,111.0
68.7730,117.0
68.8240,121.0
68.8750,128.0
68.9260,133.0
68.9770,126.0
69.0280,115.0
69.0790,114.0
69.1300,112.0
69.1810,108.0
69.2320,104.0
69.2830,114.0
69.3340,98.0
69.3850,109.0
69.4360,99.0
69.4870,96.0
69.5380,105.0
69.5890,102.0
69.6400,116.0
69.6910,105.0
69.7420,117.0
69.7930,99.0
69.8440,106.0
69.8950,119.0
69.9460,105.0
69.9970,100.0
70.0480,104.0
70.0990,96.0
70.1500,105.0
70.2010,111.0
70.2520,109.0
70.3030,103.0
70.3540,110.0
70.4050,106.0
70.4560,104.0
70.5070,97.0
70.5580,102.0
70.6090,99.0
70.6600,104.0
70.7110,104.0
70.7620,98.0
70.8130,94.0
70.8640,110.0
70.9150,114.0
70.9660,105.0
71.0170,103.0
71.0680,108.0
71.1190,119.0
71.1700,114.0
71.2210,111.0
71.2720,112.0
71.3230,118.0
71.3740,121.0
71.4250,116.0
71.4760,118.0
71.5270,120.0
71.5780,127.0
71.6290,129.0
71.6800,119.0
71.7310,118.0
71.7820,123.0
71.8330,116.0
71.8840,128.0
71.9350,125.0
71.9860,122.0
72.0370,125.0
72.0880,122.0
72.1390,109.0
72.1900,98.0
72.2410,108.0
72.2920,99.0
72.3430,100.0
72.3940,97.0
72.4450,94.0
72.4960,95.0
72.5470,99.0
72.5980,89.0
72.6490,101.0
72.7000,101.0
72.7510,79.0
72.8020,97.0
72.8530,94.0
72.9040,98.0
72.9550,98.0
73.0060,98.0
73.0570,99.0
73.1080,92.0
73.1590,95.0
73.2100,101.0
73.2610,98.0
73.3120,85.0
73.3630,85.0
73.4140,96.0
73.4650,95.0
73.5160,89.0
73.5670,100.0
73.6180,97.0
73.6690,91.0
73.7200,99.0
73.7710,108.0
73.8220,105.0
73.8730,121.0
73.9240,118.0
73.9750,137.0
74.0260,152.0
74.0770,146.0
74.1280,118.0
74.1790,100.0
74.2300,92.0
74.2810,93.0
74.3320,87.0
74.3830,99.0
74.4340,93.0
74.4850,86.0
74.5360,89.0
74.5870,91.0
74.6380,78.0
74.6890,87.0
74.7400,82.0
74.7910,88.0
74.8420,86.0
74.8930,83.0
74.9440,80.0
74.9950,82.0
75.0460,81.0
75.0970,90.0
75.1480,91.0
75.1990,86.0
75.2500,84.0
75.3010,92.0
75.3520,75.0
75.4030,80.0
75.4540,84.0
75.5050,76.0
75.5560,82.0
75.6070,82.0
75.6580,74.0
75.7090,85.0
75.7600,82.0
75.8110,75.0
75.8620,84.0
75.9130,78.0
75.9640,84.0
76.0150,87.0
76.0660,85.0
76.1170,79.0
76.1680,90.0
76.2190,81.0
76.2700,80.0
76.3210,74.0
76.3720,79.0
76.4230,80.0
76.4740,79.0
76.5250,76.0
76.5760,76.0
76.6270,73.0
76.6780,74.0
76.7290,76.0
76.7800,80.0
76.8310,74.0
76.8820,67.0
76.9330,73.0
76.9840,78.0
77.0350,83.0
77.0860,75.0
77.1370,68.0
77.1880,70.0
77.2390,82.0
77.2900,69.0
77.3410,76.0
77.3920,79.0
77.4430,83.0
77.4940,72.0
77.5450,74.0
77.5960,78.0
77.6470,73.0
77.6980,77.0
77.7490,71.0
77.8000,76.0
77.8510,76.0
77.9020,73.0
77.9530,76.0
78.0040,68.0
78.0550,72.0
78.1060,71.0
78.1570,73.0
78.2080,69.0
78.2590,77.0
78.3100,70.0
78.3610,77.0
78.4120,70.0
78.4630,72.0
78.5140,70.0
78.5650,73.0
78.6160,80.0
78.6670,73.0
78.7180,70.0
78.7690,77.0
78.8200,76.0
78.8710,70.0
78.9220,78.0
78.9730,82.0
79.0240,86.0
79.0750,76.0
79.1260,76.0
79.1770,74.0
79.2280,82.0
79.2790,71.0
79.3300,72.0
79.3810,81.0
79.4320,73.0
79.4830,71.0
79.5340,71.0
79.5850,76.0
79.6360,65.0
79.6870,78.0
79.7380,67.0
79.7890,66.0
79.8400,70.0
79.8910,67.0
79.9420,63.0
79.9930,67.0
80.0440,73.0
80.0950,72.0
80.1460,71.0
80.1970,71.0
80.2480,71.0
80.2990,73.0
80.3500,71.0
80.4010,68.0
80.4520,64.0
80.5030,70.0
80.5540,74.0
80.6050,64.0
80.6560,64.0
80.7070,69.0
80.7580,74.0
80.8090,61.0
80.8600,67.0
80.9110,67.0
80.9620,64.0
81.0130,62.0
81.0640,59.0
81.1150,73.0
81.1660,66.0
81.2170,63.0
81.2680,68.0
81.3190,70.0
81.3700,61.0
81.4210,65.0
81.4720,69.0
81.5230,70.0
81.5740,65.0
81.6250,67.0
81.6760,70.0
81.7270,63.0
81.7780,66.0
81.8290,74.0
81.8800,69.0
81.9310,69.0
81.9820,65.0
82.0330,58.0
82.0840,72.0
82.1350,66.0
82.1860,67.0
82.2370,68.0
82.2880,65.0
82.3390,69.0
82.3900,71.0
82.4410,71.0
82.4920,63.0
82.5430,68.0
82.5940,73.0
82.6450,70.0
82.6960,72.0
82.7470,79.0
82.7980,78.0
82.8490,81.0
82.9000,78.0
82.9510,78.0
83.0020,87.0
83.0530,99.0
83.1040,107.0
83.1550,106.0
83.2060,93.0
83.2570,90.0
83.3080,79.0
83.3590,82.0
83.4100,81.0
83.4610,76.0
83.5120,80.0
83.5630,70.0
83.6140,67.0
83.6650,69.0
83.7160,70.0
83.7670,64.0
83.8180,71.0
83.8690,65.0
83.9200,67.0
83.9710,65.0
84.0220,61.0
84.0730,70.0
84.1240,60.0
84.1750,67.0
84.2260,73.0
84.2770,72.0
84.3280,63.0
84.3790,67.0
84.4300,68.0
84.4810,74.0
84.5320,64.0
84.5830,65.0
84.6340,63.0
84.6850,73.0
84.7360,64.0
84.7870,68.0
84.8380,63.0
84.8890,69.0
84.9400,66.0
84.9910,63.0